<mujocoinclude>
<!-- Add hand -->
    <body name='robot0:hand' pos="0 0 0" euler="0 0 1.5707963268">

        <!-- Palm site -->
        <body name='robot0:hand_offset' pos="0 0 0.1" euler="0 0 0">
            <site name="palm" pos="0.0 0.0 0.0" euler="0 0 0" size="0.005 0.005 0.005" rgba="1 0 0 1" group="1"/>
            <site name="palm_top" pos="0.1 0.0 0.0" euler="0 0 0" size="0.005 0.005 0.005" rgba="1 1 0 1" group="1"/>
            <site name="palm_front" pos="0.0 0.0 0.1" euler="0 0 0" size="0.005 0.005 0.005" rgba="0 1 0 1" group="2"/>
            <site name="gcp" pos="0.0 0.1 0.0" euler="0 0 0" size="0.005 0.005 0.005" rgba="0 1 1 1" group="1"/>
            <site name="gcp_top" pos="-0.1 0.1 0.0" euler="0 0 0" size="0.005 0.005 0.005" rgba="0 0 1 1" group="2"/>
            <site name="palm_palmar" pos="0.0 0.1 0.0" euler="0 0 0" size="0.005 0.005 0.005" rgba="1 0 0 1" />
        </body>



        <body name="inspire_lh_palm" pos="0 0 0.0019213119733518663" quat='1 0 0 0'>
            <!-- contact site added -->
            <site name="hand_contact_site" pos="0.03 0 0.12" euler="0 0 0" size="0.05 0.05 0.05" rgba="1 0 0 0.5"/>

            <geom type="mesh" rgba="1 1 1 1" mesh="base_link"/>
            <geom pos="0.00036819 0.012296 0.1196" quat="-2.59734e-06 -2.59735e-06 0.707108 0.707105" type="mesh" rgba="0.411765 0.411765 0.411765 1" mesh="palm_force_sensor"/>
            <body name="left_thumb_1" pos="0.0269 0.02101 0.0689">
                <inertial pos="0.000892587 0.000344905 0.00159994" quat="0.985466 0.00605548 0.115048 0.124838" mass="0.00746" diaginertia="1.34891e-07 1.09691e-07 6.68155e-08"/>
                <joint name="left_thumb_1_joint" pos="0 0 0" axis="0 0 1" range="0 1.1641" damping="0.1" actuatorfrcrange="-10 10"/>
                <!-- <geom type="mesh" rgba="0.792157 0.819608 0.933333 1" mesh="left_thumb_1"/> -->
                <body name="left_thumb_2" pos="0.0073431 0.011232 0.0052" quat="0.0922934 0.0922938 -0.701059 -0.701056">
                    <inertial pos="-0.0137251 0.0122134 -0.00884794" quat="0.477951 0.518916 -0.481078 0.520435" mass="0.04364" diaginertia="1.5573e-06 1.25265e-06 1.02731e-06"/>
                    <joint name="left_thumb_2_joint" pos="0 0 0" axis="0 0 -1" range="0 0.5864" damping="0.001" actuatorfrcrange="-10 10"/>
                    <geom type="mesh" rgba="0.231373 0.480392 0.705882 1" mesh="left_thumb_2"/>
                    <geom pos="-0.0087121 0.026305 -0.0089605" quat="0.405917 -0.578993 -0.405916 -0.578991" type="mesh" rgba="0.411765 0.411765 0.411765 1" mesh="thumb_force_sensor_1"/>
                    <body name="left_thumb_3" pos="-0.031403 0.021069 -0.001299">
                        <inertial pos="-0.0109571 0.00498989 -0.00765497" quat="0.685507 0.683717 0.174884 0.178961" mass="0.01601" diaginertia="7.1124e-07 6.63577e-07 4.42249e-07"/>
                        <joint name="left_thumb_3_joint" pos="0 0 0" axis="0 0 -1" range="0 0.5" damping="0.001" actuatorfrcrange="-10 10"/>
                        <geom type="mesh" rgba="0.231373 0.580392 0.705882 1" mesh="left_thumb_3"/>
                        <geom pos="-0.011771 0.01699 -0.0077514" quat="0.428302 -0.562766 -0.428175 -0.562599" type="mesh" rgba="0.411765 0.411765 0.411765 1" mesh="thumb_force_sensor_2"/>
                        <body name="left_thumb_4" pos="-0.021903 0.012816 -0.0003">
                        <inertial pos="-0.0172132 0.0069311 -0.00734857" quat="0.642678 0.633963 0.31327 0.294819" mass="0.01172" diaginertia="1.21424e-06 1.211e-06 4.76312e-07"/>
                            <joint name="left_thumb_4_joint" pos="0 0 0" axis="0 0 -1" range="0 3.14" damping="0.001" actuatorfrcrange="-10 10"/>
                            <geom type="mesh" rgba="0.231373 0.680392 0.705882 1" mesh="left_thumb_4"/>
                            <geom pos="-0.014598 0.014721 -0.0073103" quat="0.348432 -0.615302 -0.348433 -0.615299" type="mesh" rgba="0.411765 0.411765 0.411765 1" mesh="thumb_force_sensor_3"/>
                            <geom pos="-0.028987 0.017301 -0.0073513" quat="-0.356218 0.610827 -0.356216 -0.610827" type="mesh" rgba="0.411765 0.411765 0.411765 1" mesh="thumb_force_sensor_4"/>
                        </body>
                    </body>
                </body>
            </body>
            <body name="left_index_1" pos="0.038679 0.00056467 0.1564" quat="0.508647 0.491199 -0.491201 -0.508648">
                <inertial pos="-0.00250992 0.0129748 0.00664964" quat="0.439677 0.553751 -0.439774 0.553753" mass="0.02941" diaginertia="1.30721e-06 1.21401e-06 6.04123e-07"/>
                <joint name="left_index_1_joint" pos="0 0 0" axis="0 0 1" range="0 1.4381" damping="0.01" actuatorfrcrange="-10 10"/>
                <geom type="mesh" rgba="0.513726 0.737255 0.407843 1" mesh="left_index_1"/>
                <geom pos="-0.012046 0.019649 0.006651" quat="0.701686 -0.0622873 -0.704358 -0.0873853" type="mesh" rgba="0.411765 0.411765 0.411765 1" mesh="index_force_sensor_1"/>
                <body name="left_index_2" pos="-0.0034259 0.032596 0.00055">
                    <inertial pos="-0.000626474 0.0280667 0.00609282" quat="0.701665 0.701206 0.09417 0.0843125" mass="0.01418" diaginertia="3.02123e-06 2.99824e-06 3.20601e-07"/>
                    <joint name="left_index_2_joint" pos="0 0 0" axis="0 0 1" range="0 3.14" damping="0.01" actuatorfrcrange="-10 10"/>
                    <geom type="mesh" rgba="0.613726 0.737255 0.407843 1" mesh="left_index_2"/>
                    <geom pos="-0.0081655 0.037446 0.0060795" quat="0.698536 0.13559 -0.693985 0.109758" type="mesh" rgba="0.411765 0.411765 0.411765 1" mesh="index_force_sensor_2"/>
                    <geom pos="-0.0086237 0.052572 0.0060954" quat="0.658743 -0.226725 -0.669773 -0.257017" type="mesh" rgba="0.411765 0.411765 0.411765 1" mesh="index_force_sensor_3"/>
                </body>
            </body>
            <body name="left_middle_1" pos="0.0171 0.00056467 0.157" quat="0.499998 0.5 -0.500002 -0.5">
                <inertial pos="-0.00250992 0.0129748 0.00664964" quat="0.439677 0.553752 -0.439774 0.553753" mass="0.02941" diaginertia="1.30721e-06 1.21401e-06 6.04123e-07"/>
                <joint name="left_middle_1_joint" pos="0 0 0" axis="0 0 1" range="0 1.4381" damping="0.01" actuatorfrcrange="-10 10"/>
                <geom type="mesh" rgba="0.615686 0.811765 0.729412 1" mesh="left_middle_1"/>
                <geom pos="-0.012046 0.019649 0.006651" quat="0.703134 -0.0748456 -0.703135 -0.0748437" type="mesh" rgba="0.411765 0.411765 0.411765 1" mesh="middle_force_sensor_1"/>
                <body name="left_middle_2" pos="-0.0034259 0.032596 0.00055">
                    <inertial pos="-0.00107477 0.0294281 0.00610061" quat="0.701781 0.701802 0.0864606 0.0866151" mass="0.01761" diaginertia="3.67118e-06 3.64911e-06 3.507e-07"/>
                    <joint name="left_middle_2_joint" pos="0 0 0" axis="0 0 1" range="0 3.14" damping="0.01" actuatorfrcrange="-10 10"/>
                    <geom type="mesh" rgba="0.615686 0.811765 0.929412 1" mesh="left_middle_2"/>
                    <geom pos="-0.009086 0.040962 0.0061003" quat="0.694858 0.131041 -0.694858 0.131044" type="mesh" rgba="0.411765 0.411765 0.411765 1" mesh="middle_force_sensor_2"/>
                    <geom pos="-0.0098294 0.056051 0.0061006" quat="0.667288 -0.233938 -0.667289 -0.233936" type="mesh" rgba="0.411765 0.411765 0.411765 1" mesh="middle_force_sensor_3"/>
                </body>
            </body>
            <body name="left_ring_1" pos="-0.0045302 0.00056467 0.15683" quat="0.486728 0.512927 -0.512929 -0.48673">
                <inertial pos="-0.00250992 0.0129748 0.00664964" quat="0.439676 0.553751 -0.439774 0.553754" mass="0.02941" diaginertia="1.30721e-06 1.21401e-06 6.04123e-07"/>
                <joint name="left_ring_1_joint" pos="0 0 0" axis="0 0 1" range="0 1.4381" damping="0.01" actuatorfrcrange="-10 10"/>
                <geom type="mesh" rgba="0.972549 0.529412 0.00392157 1" mesh="left_ring_1"/>
                <geom pos="-0.012046 0.019649 0.006651" quat="0.704887 -0.0936618 -0.700876 -0.0559809" type="mesh" rgba="0.411765 0.411765 0.411765 1" mesh="ring_force_sensor_1"/>
                <body name="left_ring_2" pos="-0.0034259 0.032596 0.00055">
                    <inertial pos="-0.000577147 0.0279507 0.00609282" quat="0.701659 0.701185 0.0943227 0.0843616" mass="0.01481" diaginertia="3.02641e-06 3.00354e-06 3.20717e-07"/>
                    <joint name="left_ring_2_joint" pos="0 0 0" axis="0 0 1" range="0 3.14" damping="0.01" actuatorfrcrange="-10 10"/>
                    <geom type="mesh" rgba="0.972549 0.729412 0.00392157 1" mesh="left_ring_2"/>
                    <geom pos="-0.0081655 0.037446 0.0060795" quat="0.692694 0.103257 -0.699527 0.142038" type="mesh" rgba="0.411765 0.411765 0.411765 1" mesh="ring_force_sensor_2"/>
                    <geom pos="-0.0086237 0.052572 0.0060954" quat="0.6723 -0.264487 -0.655779 -0.219118" type="mesh" rgba="0.411765 0.411765 0.411765 1" mesh="ring_force_sensor_3"/>
                </body>
            </body>
            <body name="left_little_1" pos="-0.025916 0.00056467 0.15365" quat="0.47315 0.525478 -0.52548 -0.473152">
                <inertial pos="-0.00250992 0.0129748 0.00664964" quat="0.439676 0.553751 -0.439774 0.553754" mass="0.02941" diaginertia="1.30721e-06 1.21401e-06 6.04123e-07"/>
                <joint name="left_little_1_joint" pos="0 0 0" axis="0 0 1" range="0 1.4381" damping="0.01" actuatorfrcrange="-10 10"/>
                <geom type="mesh" rgba="0.7 0.74902 0.913725 1" mesh="left_little_1"/>
                <geom pos="-0.012046 0.019649 0.006651" quat="0.706132 -0.112374 -0.69812 -0.0371073" type="mesh" rgba="0.411765 0.411765 0.411765 1" mesh="little_force_sensor_1"/>
                <body name="left_little_2" pos="-0.0034259 0.032596 0.00055">
                    <inertial pos="0.000187955 0.0230759 0.00610195" quat="0.699781 0.700085 0.0999008 0.10103" mass="0.01157" diaginertia="1.69359e-06 1.66542e-06 2.4011e-07"/>
                    <joint name="left_little_2_joint" pos="0 0 0" axis="0 0 1" range="0 3.14" damping="0.01" actuatorfrcrange="-10 10"/>
                    <geom type="mesh" rgba="0.7 0.84902 0.913725 1" mesh="left_little_2"/>
                    <geom pos="-0.0064514 0.027683 0.0061172" quat="0.689046 0.0814204 -0.702404 0.158792" type="mesh" rgba="0.411765 0.411765 0.411765 1" mesh="little_force_sensor_2"/>
                    <geom pos="-0.0063973 0.042707 0.0061154" quat="0.678772 -0.289133 -0.645293 -0.198161" type="mesh" rgba="0.411765 0.411765 0.411765 1" mesh="little_force_sensor_3"/>
                </body>
            </body>
        </body>

    </body>
</mujocoinclude>